<?xml version="1.0"?>
<robot  name="walker_a" >
 <link  name="base_link" >
  <contact >
   <lateral_friction  value="100" />
  </contact>
  <inertial >
   <inertia  izz="4.908571429"  iyy="4.51012987"  ixz="4.51012987"  iyz="0.6363636364"  ixx="0.6363636364"  ixy="4.908571429" />
   <mass  value="40" />
  </inertial>
  <visual >
   <geometry >
    <mesh  filename="body.obj"  scale="1 1 1" />
   </geometry>
  </visual>
  <collision >
   <geometry >
    <mesh  filename="body.obj"  scale="1 1 1" />
   </geometry>
  </collision>
 </link>
 <link  name="link_0_0" >
  <contact >
   <lateral_friction  value="100" />
  </contact>
  <inertial >
   <inertia  izz="0.003766478343"  iyy="0.007532956685"  ixz="0.007532956685"  iyz="0.00225"  ixx="0.000311"  ixy="0.003766478343" />
   <mass  value="2" />
   <origin />
  </inertial>
  <visual >
   <geometry >
    <mesh  filename="leg_X_0.obj"  scale="1 1 1" />
   </geometry>
  </visual>
  <collision >
   <geometry >
    <mesh  filename="leg_X_0.obj"  scale="1 1 1" />
   </geometry>
  </collision>
 </link>
 <link  name="link_0_1" >
  <contact >
   <lateral_friction  value="100" />
  </contact>
  <inertial >
   <inertia  izz="0.003766478343"  iyy="0.007532956685"  ixz="0.007532956685"  iyz="0.00225"  ixx="0.000311"  ixy="0.003766478343" />
   <mass  value="2" />
   <origin />
  </inertial>
  <visual >
   <geometry >
    <mesh  filename="leg_X_1.obj"  scale="1 1 1" />
   </geometry>
  </visual>
  <collision >
   <geometry >
    <mesh  filename="leg_X_1.obj"  scale="1 1 1" />
   </geometry>
  </collision>
 </link>
 <link  name="link_0_2" >
  <contact >
   <lateral_friction  value="100" />
  </contact>
  <inertial >
   <inertia  izz="0.003766478343"  iyy="0.007532956685"  ixz="0.007532956685"  iyz="0.00225"  ixx="0.000311"  ixy="0.003766478343" />
   <mass  value="2" />
   <origin />
  </inertial>
  <visual >
   <geometry >
    <mesh  filename="leg_X_1.obj"  scale="1 1 1" />
   </geometry>
  </visual>
  <collision >
   <geometry >
    <mesh  filename="leg_X_1.obj"  scale="1 1 1" />
   </geometry>
  </collision>
 </link>
 <link  name="link_1_0" >
  <contact >
   <lateral_friction  value="100" />
  </contact>
  <inertial >
   <inertia  izz="0.003766478343"  iyy="0.007532956685"  ixz="0.007532956685"  iyz="0.00225"  ixx="0.000311"  ixy="0.003766478343" />
   <mass  value="2" />
   <origin />
  </inertial>
  <visual >
   <geometry >
    <mesh  filename="leg_X_0.obj"  scale="1 1 1" />
   </geometry>
  </visual>
  <collision >
   <geometry >
    <mesh  filename="leg_X_0.obj"  scale="1 1 1" />
   </geometry>
  </collision>
 </link>
 <link  name="link_1_1" >
  <contact >
   <lateral_friction  value="100" />
  </contact>
  <inertial >
   <inertia  izz="0.003766478343"  iyy="0.007532956685"  ixz="0.007532956685"  iyz="0.00225"  ixx="0.000311"  ixy="0.003766478343" />
   <mass  value="2" />
   <origin />
  </inertial>
  <visual >
   <geometry >
    <mesh  filename="leg_X_1.obj"  scale="1 1 1" />
   </geometry>
  </visual>
  <collision >
   <geometry >
    <mesh  filename="leg_X_1.obj"  scale="1 1 1" />
   </geometry>
  </collision>
 </link>
 <link  name="link_1_2" >
  <contact >
   <lateral_friction  value="100" />
  </contact>
  <inertial >
   <inertia  izz="0.003766478343"  iyy="0.007532956685"  ixz="0.007532956685"  iyz="0.00225"  ixx="0.000311"  ixy="0.003766478343" />
   <mass  value="2" />
   <origin />
  </inertial>
  <visual >
   <geometry >
    <mesh  filename="leg_X_1.obj"  scale="1 1 1" />
   </geometry>
  </visual>
  <collision >
   <geometry >
    <mesh  filename="leg_X_1.obj"  scale="1 1 1" />
   </geometry>
  </collision>
 </link>
 <link  name="link_2_0" >
  <contact >
   <lateral_friction  value="100" />
  </contact>
  <inertial >
   <inertia  izz="0.003766478343"  iyy="0.007532956685"  ixz="0.007532956685"  iyz="0.00225"  ixx="0.000311"  ixy="0.003766478343" />
   <mass  value="2" />
   <origin />
  </inertial>
  <visual >
   <geometry >
    <mesh  filename="leg_X_0.obj"  scale="1 1 1" />
   </geometry>
  </visual>
  <collision >
   <geometry >
    <mesh  filename="leg_X_0.obj"  scale="1 1 1" />
   </geometry>
  </collision>
 </link>
 <link  name="link_2_1" >
  <contact >
   <lateral_friction  value="100" />
  </contact>
  <inertial >
   <inertia  izz="0.003766478343"  iyy="0.007532956685"  ixz="0.007532956685"  iyz="0.00225"  ixx="0.000311"  ixy="0.003766478343" />
   <mass  value="2" />
   <origin />
  </inertial>
  <visual >
   <geometry >
    <mesh  filename="leg_X_1.obj"  scale="1 1 1" />
   </geometry>
  </visual>
  <collision >
   <geometry >
    <mesh  filename="leg_X_1.obj"  scale="1 1 1" />
   </geometry>
  </collision>
 </link>
 <link  name="link_2_2" >
  <contact >
   <lateral_friction  value="100" />
  </contact>
  <inertial >
   <inertia  izz="0.003766478343"  iyy="0.007532956685"  ixz="0.007532956685"  iyz="0.00225"  ixx="0.000311"  ixy="0.003766478343" />
   <mass  value="2" />
   <origin />
  </inertial>
  <visual >
   <geometry >
    <mesh  filename="leg_X_1.obj"  scale="1 1 1" />
   </geometry>
  </visual>
  <collision >
   <geometry >
    <mesh  filename="leg_X_1.obj"  scale="1 1 1" />
   </geometry>
  </collision>
 </link>
 <link  name="link_3_0" >
  <contact >
   <lateral_friction  value="100" />
  </contact>
  <inertial >
   <inertia  izz="0.003766478343"  iyy="0.007532956685"  ixz="0.007532956685"  iyz="0.00225"  ixx="0.000311"  ixy="0.003766478343" />
   <mass  value="2" />
   <origin />
  </inertial>
  <visual >
   <geometry >
    <mesh  filename="leg_X_0.obj"  scale="1 1 1" />
   </geometry>
  </visual>
  <collision >
   <geometry >
    <mesh  filename="leg_X_0.obj"  scale="1 1 1" />
   </geometry>
  </collision>
 </link>
 <link  name="link_3_1" >
  <contact >
   <lateral_friction  value="100" />
  </contact>
  <inertial >
   <inertia  izz="0.003766478343"  iyy="0.007532956685"  ixz="0.007532956685"  iyz="0.00225"  ixx="0.000311"  ixy="0.003766478343" />
   <mass  value="2" />
   <origin />
  </inertial>
  <visual >
   <geometry >
    <mesh  filename="leg_X_1.obj"  scale="1 1 1" />
   </geometry>
  </visual>
  <collision >
   <geometry >
    <mesh  filename="leg_X_1.obj"  scale="1 1 1" />
   </geometry>
  </collision>
 </link>
 <link  name="link_3_2" >
  <contact >
   <lateral_friction  value="100" />
  </contact>
  <inertial >
   <inertia  izz="0.003766478343"  iyy="0.007532956685"  ixz="0.007532956685"  iyz="0.00225"  ixx="0.000311"  ixy="0.003766478343" />
   <mass  value="2" />
   <origin />
  </inertial>
  <visual >
   <geometry >
    <mesh  filename="leg_X_1.obj"  scale="1 1 1" />
   </geometry>
  </visual>
  <collision >
   <geometry >
    <mesh  filename="leg_X_1.obj"  scale="1 1 1" />
   </geometry>
  </collision>
 </link>
 <joint  name="joint_0_0"  type="continuous" >
  <parent  link="base_link" />
  <child  link="link_0_0" />
  <origin  rpy="0, 0, 0"  xyz="0.35, -0.3, 0" />
  <axis  xyz="1, 0, 0" />
 </joint>
 <joint  name="joint_0_1"  type="continuous" >
  <parent  link="link_0_0" />
  <child  link="link_0_1" />
  <origin  xyz="0.15, 0, 0" />
  <axis  xyz="0, 1, 0" />
 </joint>
 <joint  name="joint_0_2"  type="continuous" >
  <parent  link="link_0_1" />
  <child  link="link_0_2" />
  <origin  xyz="0, 0, -0.5" />
  <axis  xyz="0, 1, 0" />
 </joint>
 <joint  name="joint_1_0"  type="continuous" >
  <parent  link="base_link" />
  <child  link="link_1_0" />
  <origin  rpy="0, 0, 0"  xyz="0.35, 0.3, 0" />
  <axis  xyz="1, 0, 0" />
 </joint>
 <joint  name="joint_1_1"  type="continuous" >
  <parent  link="link_1_0" />
  <child  link="link_1_1" />
  <origin  xyz="0.15, 0, 0" />
  <axis  xyz="0, 1, 0" />
 </joint>
 <joint  name="joint_1_2"  type="continuous" >
  <parent  link="link_1_1" />
  <child  link="link_1_2" />
  <origin  xyz="0, 0, -0.5" />
  <axis  xyz="0, 1, 0" />
 </joint>
 <joint  name="joint_2_0"  type="continuous" >
  <parent  link="base_link" />
  <child  link="link_2_0" />
  <origin  rpy="0, 0, 3.14159"  xyz="-0.35, 0.3, 0" />
  <axis  xyz="1, 0, 0" />
 </joint>
 <joint  name="joint_2_1"  type="continuous" >
  <parent  link="link_2_0" />
  <child  link="link_2_1" />
  <origin  xyz="0.15, 0, 0" />
  <axis  xyz="0, 1, 0" />
 </joint>
 <joint  name="joint_2_2"  type="continuous" >
  <parent  link="link_2_1" />
  <child  link="link_2_2" />
  <origin  xyz="0, 0, -0.5" />
  <axis  xyz="0, 1, 0" />
 </joint>
 <joint  name="joint_3_0"  type="continuous" >
  <parent  link="base_link" />
  <child  link="link_3_0" />
  <origin  rpy="0, 0, 3.14159"  xyz="-0.35, -0.3, 0" />
  <axis  xyz="1, 0, 0" />
 </joint>
 <joint  name="joint_3_1"  type="continuous" >
  <parent  link="link_3_0" />
  <child  link="link_3_1" />
  <origin  xyz="0.15, 0, 0" />
  <axis  xyz="0, 1, 0" />
 </joint>
 <joint  name="joint_3_2"  type="continuous" >
  <parent  link="link_3_1" />
  <child  link="link_3_2" />
  <origin  xyz="0, 0, -0.5" />
  <axis  xyz="0, 1, 0" />
 </joint>
</robot>
